<?xml version="1.0" encoding="utf-8"?>
<!-- This URDF was automatically created by SolidWorks to URDF Exporter! Originally created by Stephen Brawner (brawner@gmail.com) 
     Commit Version: 1.6.0-4-g7f85cfe  Build Version: 1.6.7995.38578
     For more information, please see http://wiki.ros.org/sw_urdf_exporter -->
<robot
  name="CERBERUS_V1">
  <link
    name="M">
    <inertial>
      <origin
        xyz="-0.00013997 0.00012538 0.013885"
        rpy="0 0 0" />
      <mass
        value="0.26104" />
      <inertia
        ixx="0.00040065"
        ixy="-3.5505E-08"
        ixz="8.1973E-08"
        iyy="0.0011658"
        iyz="-5.4402E-08"
        izz="0.0015373" />
    </inertial>
    <visual>
      <origin
        xyz="0 0 0"
        rpy="0 0 0" />
      <geometry>
        <mesh
          filename="package://CERBERUS_V1/meshes/M.STL" />
      </geometry>
      <material
        name="">
        <color
          rgba="1 1 1 1" />
      </material>
    </visual>
    <collision>
      <origin
        xyz="0 0 0"
        rpy="0 0 0" />
      <geometry>
        <mesh
          filename="package://CERBERUS_V1/meshes/M.STL" />
      </geometry>
    </collision>
  </link>
  <link
    name="BODY">
    <inertial>
      <origin
        xyz="-0.034085 4.3078E-06 0.067864"
        rpy="0 0 0" />
      <mass
        value="0.88698" />
      <inertia
        ixx="0.0071834"
        ixy="6.0268E-09"
        ixz="-0.00054163"
        iyy="0.0046986"
        iyz="-8.2586E-08"
        izz="0.0083988" />
    </inertial>
    <visual>
      <origin
        xyz="0 0 0"
        rpy="0 0 0" />
      <geometry>
        <mesh
          filename="package://CERBERUS_V1/meshes/BODY.STL" />
      </geometry>
      <material
        name="">
        <color
          rgba="0.5451 0.61569 0.85882 1" />
      </material>
    </visual>
    <collision>
      <origin
        xyz="0 0 0"
        rpy="0 0 0" />
      <geometry>
        <mesh
          filename="package://CERBERUS_V1/meshes/BODY.STL" />
      </geometry>
    </collision>
  </link>
  <joint
    name="BODY_M"
    type="fixed">
    <origin
      xyz="0.075 0 0.003"
      rpy="0 0 0" />
    <parent
      link="M" />
    <child
      link="BODY" />
    <axis
      xyz="0 0 0" />
  </joint>
  <link
    name="CAMERA">
    <inertial>
      <origin
        xyz="-0.02622 -8.6647E-06 -0.015032"
        rpy="0 0 0" />
      <mass
        value="0.30222" />
      <inertia
        ixx="0.00048121"
        ixy="4.8053E-08"
        ixz="-8.8179E-06"
        iyy="0.00012834"
        iyz="-8.6714E-10"
        izz="0.00053556" />
    </inertial>
    <visual>
      <origin
        xyz="0 0 0"
        rpy="0 0 0" />
      <geometry>
        <mesh
          filename="package://CERBERUS_V1/meshes/CAMERA.STL" />
      </geometry>
      <material
        name="">
        <color
          rgba="0.25098 0.25098 0.25098 1" />
      </material>
    </visual>
    <collision>
      <origin
        xyz="0 0 0"
        rpy="0 0 0" />
      <geometry>
        <mesh
          filename="package://CERBERUS_V1/meshes/CAMERA.STL" />
      </geometry>
    </collision>
  </link>
  <joint
    name="CAMERA_M"
    type="fixed">
    <origin
      xyz="0.22987 0 0.09815"
      rpy="0 0 0" />
    <parent
      link="M" />
    <child
      link="CAMERA" />
    <axis
      xyz="0 0 0" />
  </joint>
  <link
    name="LIDAR">
    <inertial>
      <origin
        xyz="0.0019924 0.00034039 -0.0014487"
        rpy="0 0 0" />
      <mass
        value="0.10143" />
      <inertia
        ixx="0.00010664"
        ixy="-3.0202E-08"
        ixz="1.0682E-08"
        iyy="7.1321E-05"
        iyz="4.5081E-08"
        izz="0.00017021" />
    </inertial>
    <visual>
      <origin
        xyz="0 0 0"
        rpy="0 0 0" />
      <geometry>
        <mesh
          filename="package://CERBERUS_V1/meshes/LIDAR.STL" />
      </geometry>
      <material
        name="">
        <color
          rgba="0.25098 0.25098 0.25098 1" />
      </material>
    </visual>
    <collision>
      <origin
        xyz="0 0 0"
        rpy="0 0 0" />
      <geometry>
        <mesh
          filename="package://CERBERUS_V1/meshes/LIDAR.STL" />
      </geometry>
    </collision>
  </link>
  <joint
    name="LIDAR_M"
    type="fixed">
    <origin
      xyz="0.072975 2.5E-05 0.14436"
      rpy="0 0 0" />
    <parent
      link="M" />
    <child
      link="LIDAR" />
    <axis
      xyz="0 0 0" />
  </joint>
  <link
    name="IMU0C">
    <inertial>
      <origin
        xyz="-1.3878E-17 1.402E-19 0.0015"
        rpy="0 0 0" />
      <mass
        value="0.0009" />
      <inertia
        ixx="1.755E-08"
        ixy="8.2718E-25"
        ixz="-2.077E-25"
        iyy="3.0675E-08"
        iyz="3.9568E-25"
        izz="4.6875E-08" />
    </inertial>
    <visual>
      <origin
        xyz="0 0 0"
        rpy="0 0 0" />
      <geometry>
        <mesh
          filename="package://CERBERUS_V1/meshes/IMU0C.STL" />
      </geometry>
      <material
        name="">
        <color
          rgba="0 1 0 1" />
      </material>
    </visual>
    <collision>
      <origin
        xyz="0 0 0"
        rpy="0 0 0" />
      <geometry>
        <mesh
          filename="package://CERBERUS_V1/meshes/IMU0C.STL" />
      </geometry>
    </collision>
  </link>
  <joint
    name="IMU0C_M"
    type="fixed">
    <origin
      xyz="0.075 0 0.12916"
      rpy="0 0 0" />
    <parent
      link="M" />
    <child
      link="IMU0C" />
    <axis
      xyz="0 0 0" />
  </joint>
  <link
    name="SeFR">
    <inertial>
      <origin
        xyz="0.00039965 -0.00024478 0.025144"
        rpy="0 0 0" />
      <mass
        value="0.037021" />
      <inertia
        ixx="5.4169E-06"
        ixy="-9.1221E-09"
        ixz="-2.0494E-08"
        iyy="5.0821E-06"
        iyz="1.3847E-08"
        izz="3.2296E-06" />
    </inertial>
    <visual>
      <origin
        xyz="0 0 0"
        rpy="0 0 0" />
      <geometry>
        <mesh
          filename="package://CERBERUS_V1/meshes/SeFR.STL" />
      </geometry>
      <material
        name="">
        <color
          rgba="0.89804 0.91765 0.92941 1" />
      </material>
    </visual>
    <collision>
      <origin
        xyz="0 0 0"
        rpy="0 0 0" />
      <geometry>
        <mesh
          filename="package://CERBERUS_V1/meshes/SeFR.STL" />
      </geometry>
    </collision>
  </link>
  <joint
    name="SeFR_M"
    type="revolute">
    <origin
      xyz="0.1446 -0.095 0.044"
      rpy="1.5708 0 1.5708" />
    <parent
      link="M" />
    <child
      link="SeFR" />
    <axis
      xyz="0 0 -1" />
    <limit
      lower="-0.7854"
      upper="0.7854"
      effort="1.7"
      velocity="6.545" />
    <dynamics
      damping="0.025"
      friction="0.12" />
    <safety_controller
      soft_upper_limit="0.7"
      soft_lower_limit="-0.7"
      k_velocity="0" />
  </joint>
  <link
    name="ThFR">
    <inertial>
      <origin
        xyz="0.065249 -0.0067576 0.024445"
        rpy="0 0 0" />
      <mass
        value="0.2297" />
      <inertia
        ixx="4.5425E-05"
        ixy="2.0512E-05"
        ixz="-4.5527E-06"
        iyy="0.00063156"
        iyz="-6.7477E-07"
        izz="0.00064269" />
    </inertial>
    <visual>
      <origin
        xyz="0 0 0"
        rpy="0 0 0" />
      <geometry>
        <mesh
          filename="package://CERBERUS_V1/meshes/ThFR.STL" />
      </geometry>
      <material
        name="">
        <color
          rgba="0.89804 0.91765 0.92941 1" />
      </material>
    </visual>
    <collision>
      <origin
        xyz="0 0 0"
        rpy="0 0 0" />
      <geometry>
        <mesh
          filename="package://CERBERUS_V1/meshes/ThFR.STL" />
      </geometry>
    </collision>
  </link>
  <joint
    name="ThFR_SeFR"
    type="revolute">
    <origin
      xyz="-0.0144 -2.8116E-05 0.045901"
      rpy="1.5708 0.70755 -1.5708" />
    <parent
      link="SeFR" />
    <child
      link="ThFR" />
    <axis
      xyz="0 0 -1" />
    <limit
      lower="-0.7854"
      upper="0.7854"
      effort="1.7"
      velocity="6.545" />
    <dynamics
      damping="0.025"
      friction="0.12" />
    <safety_controller
      soft_upper_limit="0.7"
      soft_lower_limit="-0.7"
      k_velocity="0" />
  </joint>
  <link
    name="ArFR">
    <inertial>
      <origin
        xyz="-2.7735E-05 0.007627 0.0033028"
        rpy="0 0 0" />
      <mass
        value="0.0030347" />
      <inertia
        ixx="2.989E-07"
        ixy="4.865E-09"
        ixz="2.5487E-11"
        iyy="4.3267E-08"
        iyz="-5.0977E-09"
        izz="3.2577E-07" />
    </inertial>
    <visual>
      <origin
        xyz="0 0 0"
        rpy="0 0 0" />
      <geometry>
        <mesh
          filename="package://CERBERUS_V1/meshes/ArFR.STL" />
      </geometry>
      <material
        name="">
        <color
          rgba="0.89804 0.91765 0.92941 1" />
      </material>
    </visual>
    <collision>
      <origin
        xyz="0 0 0"
        rpy="0 0 0" />
      <geometry>
        <mesh
          filename="package://CERBERUS_V1/meshes/ArFR.STL" />
      </geometry>
    </collision>
  </link>
  <joint
    name="ArFR_ThFR"
    type="revolute">
    <origin
      xyz="0.050268 -0.027324 0.025223"
      rpy="1.5708 0 0" />
    <parent
      link="ThFR" />
    <child
      link="ArFR" />
    <axis
      xyz="0 0 -1" />
    <limit
      lower="-0.7854"
      upper="0.7854"
      effort="1.7"
      velocity="6.545" />
    <dynamics
      damping="0.025"
      friction="0.12" />
    <safety_controller
      soft_upper_limit="0.7"
      soft_lower_limit="-0.7"
      k_velocity="0" />
  </joint>
  <link
    name="IMU1FR">
    <inertial>
      <origin
        xyz="0 0 0.0015"
        rpy="0 0 0" />
      <mass
        value="0.0009" />
      <inertia
        ixx="1.755E-08"
        ixy="-2.4815E-24"
        ixz="-1.6578E-24"
        iyy="3.0675E-08"
        iyz="4.867E-25"
        izz="4.6875E-08" />
    </inertial>
    <visual>
      <origin
        xyz="0 0 0"
        rpy="0 0 0" />
      <geometry>
        <mesh
          filename="package://CERBERUS_V1/meshes/IMU1FR.STL" />
      </geometry>
      <material
        name="">
        <color
          rgba="0 1 0 1" />
      </material>
    </visual>
    <collision>
      <origin
        xyz="0 0 0"
        rpy="0 0 0" />
      <geometry>
        <mesh
          filename="package://CERBERUS_V1/meshes/IMU1FR.STL" />
      </geometry>
    </collision>
  </link>
  <joint
    name="IMU1FR_ThFR"
    type="fixed">
    <origin
      xyz="0.079757 -0.006231 0.04015"
      rpy="0 0 3.0636" />
    <parent
      link="ThFR" />
    <child
      link="IMU1FR" />
    <axis
      xyz="0 0 0" />
  </joint>
  <link
    name="ShFR">
    <inertial>
      <origin
        xyz="-0.067367 -0.0073554 0.014841"
        rpy="0 0 0" />
      <mass
        value="0.088995" />
      <inertia
        ixx="1.0044E-05"
        ixy="-1.8089E-05"
        ixz="3.9307E-09"
        iyy="0.00024333"
        iyz="1.2555E-10"
        izz="0.00024934" />
    </inertial>
    <visual>
      <origin
        xyz="0 0 0"
        rpy="0 0 0" />
      <geometry>
        <mesh
          filename="package://CERBERUS_V1/meshes/ShFR.STL" />
      </geometry>
      <material
        name="">
        <color
          rgba="0.5451 0.61569 0.85882 1" />
      </material>
    </visual>
    <collision>
      <origin
        xyz="0 0 0"
        rpy="0 0 0" />
      <geometry>
        <mesh
          filename="package://CERBERUS_V1/meshes/ShFR.STL" />
      </geometry>
    </collision>
  </link>
  <joint
    name="ShFR_ThFR"
    type="revolute">
    <origin
      xyz="0.18101 0.0059195 0.01015"
      rpy="0 0 -1.6488" />
    <parent
      link="ThFR" />
    <child
      link="ShFR" />
    <axis
      xyz="0 0 -1" />
    <limit
      lower="-0.7854"
      upper="0.7854"
      effort="1.7"
      velocity="6.545" />
    <dynamics
      damping="0.025"
      friction="0.12" />
    <safety_controller
      soft_upper_limit="0.7"
      soft_lower_limit="-0.7"
      k_velocity="0" />
    <mimic
      joint="ArFR_ThFR"
      multiplier="-0.2824"
      offset="0" />
  </joint>
  <link
    name="IMU2FR">
    <inertial>
      <origin
        xyz="1.4988E-15 -1.1935E-15 0.0015"
        rpy="0 0 0" />
      <mass
        value="0.0009" />
      <inertia
        ixx="1.755E-08"
        ixy="-2.6185E-23"
        ixz="1.5249E-24"
        iyy="3.0675E-08"
        iyz="-7.5566E-24"
        izz="4.6875E-08" />
    </inertial>
    <visual>
      <origin
        xyz="0 0 0"
        rpy="0 0 0" />
      <geometry>
        <mesh
          filename="package://CERBERUS_V1/meshes/IMU2FR.STL" />
      </geometry>
      <material
        name="">
        <color
          rgba="0 1 0 1" />
      </material>
    </visual>
    <collision>
      <origin
        xyz="0 0 0"
        rpy="0 0 0" />
      <geometry>
        <mesh
          filename="package://CERBERUS_V1/meshes/IMU2FR.STL" />
      </geometry>
    </collision>
  </link>
  <joint
    name="IMU2FR_ShFR"
    type="fixed">
    <origin
      xyz="-0.16803 0.013888 0.024775"
      rpy="0 0 -0.76282" />
    <parent
      link="ShFR" />
    <child
      link="IMU2FR" />
    <axis
      xyz="0 0 0" />
  </joint>
  <link
    name="SeBR">
    <inertial>
      <origin
        xyz="0.00039965 -0.00024478 0.025144"
        rpy="0 0 0" />
      <mass
        value="0.037021" />
      <inertia
        ixx="5.4169E-06"
        ixy="-9.1221E-09"
        ixz="-2.0494E-08"
        iyy="5.0821E-06"
        iyz="1.3847E-08"
        izz="3.2296E-06" />
    </inertial>
    <visual>
      <origin
        xyz="0 0 0"
        rpy="0 0 0" />
      <geometry>
        <mesh
          filename="package://CERBERUS_V1/meshes/SeBR.STL" />
      </geometry>
      <material
        name="">
        <color
          rgba="0.89804 0.91765 0.92941 1" />
      </material>
    </visual>
    <collision>
      <origin
        xyz="0 0 0"
        rpy="0 0 0" />
      <geometry>
        <mesh
          filename="package://CERBERUS_V1/meshes/SeBR.STL" />
      </geometry>
    </collision>
  </link>
  <joint
    name="SeBR_M"
    type="revolute">
    <origin
      xyz="-0.1154 -0.095 0.044"
      rpy="1.5708 0 1.5708" />
    <parent
      link="M" />
    <child
      link="SeBR" />
    <axis
      xyz="0 0 -1" />
    <limit
      lower="-0.7854"
      upper="0.7854"
      effort="1.7"
      velocity="6.545" />
    <dynamics
      damping="0.025"
      friction="0.12" />
    <safety_controller
      soft_upper_limit="0.7"
      soft_lower_limit="-0.7"
      k_velocity="0" />
  </joint>
  <link
    name="ThBR">
    <inertial>
      <origin
        xyz="0.065249 -0.0067576 0.024445"
        rpy="0 0 0" />
      <mass
        value="0.2297" />
      <inertia
        ixx="4.5425E-05"
        ixy="2.0512E-05"
        ixz="-4.5527E-06"
        iyy="0.00063156"
        iyz="-6.7477E-07"
        izz="0.00064269" />
    </inertial>
    <visual>
      <origin
        xyz="0 0 0"
        rpy="0 0 0" />
      <geometry>
        <mesh
          filename="package://CERBERUS_V1/meshes/ThBR.STL" />
      </geometry>
      <material
        name="">
        <color
          rgba="0.89804 0.91765 0.92941 1" />
      </material>
    </visual>
    <collision>
      <origin
        xyz="0 0 0"
        rpy="0 0 0" />
      <geometry>
        <mesh
          filename="package://CERBERUS_V1/meshes/ThBR.STL" />
      </geometry>
    </collision>
  </link>
  <joint
    name="ThBR_SeBR"
    type="revolute">
    <origin
      xyz="-0.0144 -2.8116E-05 0.045901"
      rpy="1.5708 0.70755 -1.5708" />
    <parent
      link="SeBR" />
    <child
      link="ThBR" />
    <axis
      xyz="0 0 -1" />
    <limit
      lower="-0.7854"
      upper="0.7854"
      effort="1.7"
      velocity="6.545" />
    <dynamics
      damping="0.025"
      friction="0.12" />
    <safety_controller
      soft_upper_limit="0.7"
      soft_lower_limit="-0.7"
      k_velocity="0" />
  </joint>
  <link
    name="ArBR">
    <inertial>
      <origin
        xyz="-2.7735E-05 0.007627 0.0033028"
        rpy="0 0 0" />
      <mass
        value="0.0030347" />
      <inertia
        ixx="2.989E-07"
        ixy="4.865E-09"
        ixz="2.5487E-11"
        iyy="4.3267E-08"
        iyz="-5.0977E-09"
        izz="3.2577E-07" />
    </inertial>
    <visual>
      <origin
        xyz="0 0 0"
        rpy="0 0 0" />
      <geometry>
        <mesh
          filename="package://CERBERUS_V1/meshes/ArBR.STL" />
      </geometry>
      <material
        name="">
        <color
          rgba="0.89804 0.91765 0.92941 1" />
      </material>
    </visual>
    <collision>
      <origin
        xyz="0 0 0"
        rpy="0 0 0" />
      <geometry>
        <mesh
          filename="package://CERBERUS_V1/meshes/ArBR.STL" />
      </geometry>
    </collision>
  </link>
  <joint
    name="ArBR_ThBR"
    type="revolute">
    <origin
      xyz="0.050268 -0.027324 0.025223"
      rpy="1.5708 0 0" />
    <parent
      link="ThBR" />
    <child
      link="ArBR" />
    <axis
      xyz="0 0 -1" />
    <limit
      lower="-0.7854"
      upper="0.7854"
      effort="1.7"
      velocity="6.545" />
    <dynamics
      damping="0.025"
      friction="0.12" />
    <safety_controller
      soft_upper_limit="0.7"
      soft_lower_limit="-0.7"
      k_velocity="0" />
  </joint>
  <link
    name="IMU1BR">
    <inertial>
      <origin
        xyz="0 0 0.0015"
        rpy="0 0 0" />
      <mass
        value="0.0009" />
      <inertia
        ixx="1.755E-08"
        ixy="-4.9631E-24"
        ixz="-2.8023E-24"
        iyy="3.0675E-08"
        iyz="2.3016E-24"
        izz="4.6875E-08" />
    </inertial>
    <visual>
      <origin
        xyz="0 0 0"
        rpy="0 0 0" />
      <geometry>
        <mesh
          filename="package://CERBERUS_V1/meshes/IMU1BR.STL" />
      </geometry>
      <material
        name="">
        <color
          rgba="0 1 0 1" />
      </material>
    </visual>
    <collision>
      <origin
        xyz="0 0 0"
        rpy="0 0 0" />
      <geometry>
        <mesh
          filename="package://CERBERUS_V1/meshes/IMU1BR.STL" />
      </geometry>
    </collision>
  </link>
  <joint
    name="IMU1BR_ThBR"
    type="fixed">
    <origin
      xyz="0.079757 -0.006231 0.04015"
      rpy="0 0 3.0636" />
    <parent
      link="ThBR" />
    <child
      link="IMU1BR" />
    <axis
      xyz="0 0 0" />
  </joint>
  <link
    name="ShBR">
    <inertial>
      <origin
        xyz="-0.067367 -0.0073554 0.014841"
        rpy="0 0 0" />
      <mass
        value="0.088995" />
      <inertia
        ixx="1.0044E-05"
        ixy="-1.8089E-05"
        ixz="3.9308E-09"
        iyy="0.00024333"
        iyz="1.2556E-10"
        izz="0.00024934" />
    </inertial>
    <visual>
      <origin
        xyz="0 0 0"
        rpy="0 0 0" />
      <geometry>
        <mesh
          filename="package://CERBERUS_V1/meshes/ShBR.STL" />
      </geometry>
      <material
        name="">
        <color
          rgba="0.5451 0.61569 0.85882 1" />
      </material>
    </visual>
    <collision>
      <origin
        xyz="0 0 0"
        rpy="0 0 0" />
      <geometry>
        <mesh
          filename="package://CERBERUS_V1/meshes/ShBR.STL" />
      </geometry>
    </collision>
  </link>
  <joint
    name="ShBR_ThBR"
    type="revolute">
    <origin
      xyz="0.18101 0.0059195 0.01015"
      rpy="0 0 -1.6488" />
    <parent
      link="ThBR" />
    <child
      link="ShBR" />
    <axis
      xyz="0 0 -1" />
    <limit
      lower="-0.7854"
      upper="0.7854"
      effort="1.7"
      velocity="6.545" />
    <dynamics
      damping="0.025"
      friction="0.12" />
    <safety_controller
      soft_upper_limit="0.7"
      soft_lower_limit="-0.7"
      k_velocity="0" />
    <mimic
      joint="ArBR_ThBR"
      multiplier="-0.2824"
      offset="0" />
  </joint>
  <link
    name="IMU2BR">
    <inertial>
      <origin
        xyz="1.4988E-15 -1.1519E-15 0.0015"
        rpy="0 0 0" />
      <mass
        value="0.0009" />
      <inertia
        ixx="1.755E-08"
        ixy="-3.2674E-23"
        ixz="1.3527E-25"
        iyy="3.0675E-08"
        iyz="-7.7142E-24"
        izz="4.6875E-08" />
    </inertial>
    <visual>
      <origin
        xyz="0 0 0"
        rpy="0 0 0" />
      <geometry>
        <mesh
          filename="package://CERBERUS_V1/meshes/IMU2BR.STL" />
      </geometry>
      <material
        name="">
        <color
          rgba="0 1 0 1" />
      </material>
    </visual>
    <collision>
      <origin
        xyz="0 0 0"
        rpy="0 0 0" />
      <geometry>
        <mesh
          filename="package://CERBERUS_V1/meshes/IMU2BR.STL" />
      </geometry>
    </collision>
  </link>
  <joint
    name="IMU2BR_ShBR"
    type="fixed">
    <origin
      xyz="-0.16803 0.013888 0.024775"
      rpy="0 0 -0.76282" />
    <parent
      link="ShBR" />
    <child
      link="IMU2BR" />
    <axis
      xyz="0 0 0" />
  </joint>
  <link
    name="SeFL">
    <inertial>
      <origin
        xyz="-0.00039965 0.00024478 0.025144"
        rpy="0 0 0" />
      <mass
        value="0.037021" />
      <inertia
        ixx="5.4169E-06"
        ixy="-9.1221E-09"
        ixz="2.0494E-08"
        iyy="5.0821E-06"
        iyz="-1.3847E-08"
        izz="3.2296E-06" />
    </inertial>
    <visual>
      <origin
        xyz="0 0 0"
        rpy="0 0 0" />
      <geometry>
        <mesh
          filename="package://CERBERUS_V1/meshes/SeFL.STL" />
      </geometry>
      <material
        name="">
        <color
          rgba="0.89804 0.91765 0.92941 1" />
      </material>
    </visual>
    <collision>
      <origin
        xyz="0 0 0"
        rpy="0 0 0" />
      <geometry>
        <mesh
          filename="package://CERBERUS_V1/meshes/SeFL.STL" />
      </geometry>
    </collision>
  </link>
  <joint
    name="SeFL_M"
    type="revolute">
    <origin
      xyz="0.1446 0.095 0.044"
      rpy="1.5708 0 1.5708" />
    <parent
      link="M" />
    <child
      link="SeFL" />
    <axis
      xyz="0 0 -1" />
    <limit
      lower="-0.7854"
      upper="0.7854"
      effort="1.7"
      velocity="6.545" />
    <dynamics
      damping="0.025"
      friction="0.12" />
    <safety_controller
      soft_upper_limit="0.7"
      soft_lower_limit="-0.7"
      k_velocity="0" />
  </joint>
  <link
    name="ThFL">
    <inertial>
      <origin
        xyz="-0.065249 -0.0067576 0.024344"
        rpy="0 0 0" />
      <mass
        value="0.2297" />
      <inertia
        ixx="4.5425E-05"
        ixy="-2.0512E-05"
        ixz="4.5799E-06"
        iyy="0.00063156"
        iyz="-6.9302E-07"
        izz="0.00064269" />
    </inertial>
    <visual>
      <origin
        xyz="0 0 0"
        rpy="0 0 0" />
      <geometry>
        <mesh
          filename="package://CERBERUS_V1/meshes/ThFL.STL" />
      </geometry>
      <material
        name="">
        <color
          rgba="0.89804 0.91765 0.92941 1" />
      </material>
    </visual>
    <collision>
      <origin
        xyz="0 0 0"
        rpy="0 0 0" />
      <geometry>
        <mesh
          filename="package://CERBERUS_V1/meshes/ThFL.STL" />
      </geometry>
    </collision>
  </link>
  <joint
    name="ThFL_SeFL"
    type="revolute">
    <origin
      xyz="0.0144 2.8116E-05 0.045901"
      rpy="1.5708 -0.70732 1.5708" />
    <parent
      link="SeFL" />
    <child
      link="ThFL" />
    <axis
      xyz="0 0 -1" />
    <limit
      lower="-0.7854"
      upper="0.7854"
      effort="1.7"
      velocity="6.545" />
    <dynamics
      damping="0.025"
      friction="0.12" />
    <safety_controller
      soft_upper_limit="0.7"
      soft_lower_limit="-0.7"
      k_velocity="0" />
  </joint>
  <link
    name="ArFL">
    <inertial>
      <origin
        xyz="-2.7735E-05 0.007627 0.0033028"
        rpy="0 0 0" />
      <mass
        value="0.0030347" />
      <inertia
        ixx="2.989E-07"
        ixy="4.865E-09"
        ixz="2.5487E-11"
        iyy="4.3267E-08"
        iyz="-5.0977E-09"
        izz="3.2577E-07" />
    </inertial>
    <visual>
      <origin
        xyz="0 0 0"
        rpy="0 0 0" />
      <geometry>
        <mesh
          filename="package://CERBERUS_V1/meshes/ArFL.STL" />
      </geometry>
      <material
        name="">
        <color
          rgba="0.89804 0.91765 0.92941 1" />
      </material>
    </visual>
    <collision>
      <origin
        xyz="0 0 0"
        rpy="0 0 0" />
      <geometry>
        <mesh
          filename="package://CERBERUS_V1/meshes/ArFL.STL" />
      </geometry>
    </collision>
  </link>
  <joint
    name="ArFL_ThFL"
    type="revolute">
    <origin
      xyz="-0.050268 -0.027324 0.025077"
      rpy="1.5708 0 0" />
    <parent
      link="ThFL" />
    <child
      link="ArFL" />
    <axis
      xyz="0 0 -1" />
    <limit
      lower="-0.7854"
      upper="0.7854"
      effort="1.7"
      velocity="6.545" />
    <dynamics
      damping="0.025"
      friction="0.12" />
    <safety_controller
      soft_upper_limit="0.7"
      soft_lower_limit="-0.7"
      k_velocity="0" />
  </joint>
  <link
    name="IMU1FL">
    <inertial>
      <origin
        xyz="0 0 0.0015"
        rpy="0 0 0" />
      <mass
        value="0.0009" />
      <inertia
        ixx="1.755E-08"
        ixy="3.3087E-24"
        ixz="1.2895E-23"
        iyy="3.0675E-08"
        iyz="7.5407E-24"
        izz="4.6875E-08" />
    </inertial>
    <visual>
      <origin
        xyz="0 0 0"
        rpy="0 0 0" />
      <geometry>
        <mesh
          filename="package://CERBERUS_V1/meshes/IMU1FL.STL" />
      </geometry>
      <material
        name="">
        <color
          rgba="0 1 0 1" />
      </material>
    </visual>
    <collision>
      <origin
        xyz="0 0 0"
        rpy="0 0 0" />
      <geometry>
        <mesh
          filename="package://CERBERUS_V1/meshes/IMU1FL.STL" />
      </geometry>
    </collision>
  </link>
  <joint
    name="IMU1FL_ThFL"
    type="fixed">
    <origin
      xyz="-0.079757 -0.006231 0.04015"
      rpy="0 0 0.077967" />
    <parent
      link="ThFL" />
    <child
      link="IMU1FL" />
    <axis
      xyz="0 0 0" />
  </joint>
  <link
    name="ShFL">
    <inertial>
      <origin
        xyz="0.067367 -0.0073554 0.01484"
        rpy="0 0 0" />
      <mass
        value="0.088995" />
      <inertia
        ixx="1.0044E-05"
        ixy="1.8089E-05"
        ixz="3.9307E-09"
        iyy="0.00024333"
        iyz="-1.2554E-10"
        izz="0.00024934" />
    </inertial>
    <visual>
      <origin
        xyz="0 0 0"
        rpy="0 0 0" />
      <geometry>
        <mesh
          filename="package://CERBERUS_V1/meshes/ShFL.STL" />
      </geometry>
      <material
        name="">
        <color
          rgba="0.5451 0.61569 0.85882 1" />
      </material>
    </visual>
    <collision>
      <origin
        xyz="0 0 0"
        rpy="0 0 0" />
      <geometry>
        <mesh
          filename="package://CERBERUS_V1/meshes/ShFL.STL" />
      </geometry>
    </collision>
  </link>
  <joint
    name="ShFL_ThFL"
    type="revolute">
    <origin
      xyz="-0.18101 0.0059195 0.01015"
      rpy="0 0 1.6483" />
    <parent
      link="ThFL" />
    <child
      link="ShFL" />
    <axis
      xyz="0 0 -1" />
    <limit
      lower="-0.7854"
      upper="0.7854"
      effort="1.7"
      velocity="6.545" />
    <dynamics
      damping="0.025"
      friction="0.12" />
    <safety_controller
      soft_upper_limit="0.7"
      soft_lower_limit="-0.7"
      k_velocity="0" />
    <mimic
      joint="ArFL_ThFL"
      multiplier="-0.2824"
      offset="0" />
  </joint>
  <link
    name="IMU2FL">
    <inertial>
      <origin
        xyz="3.6082E-16 -3.0531E-16 0.0015"
        rpy="0 0 0" />
      <mass
        value="0.0009" />
      <inertia
        ixx="1.755E-08"
        ixy="-1.0676E-23"
        ixz="1.0751E-23"
        iyy="3.0675E-08"
        iyz="2.5305E-24"
        izz="4.6875E-08" />
    </inertial>
    <visual>
      <origin
        xyz="0 0 0"
        rpy="0 0 0" />
      <geometry>
        <mesh
          filename="package://CERBERUS_V1/meshes/IMU2FL.STL" />
      </geometry>
      <material
        name="">
        <color
          rgba="0 1 0 1" />
      </material>
    </visual>
    <collision>
      <origin
        xyz="0 0 0"
        rpy="0 0 0" />
      <geometry>
        <mesh
          filename="package://CERBERUS_V1/meshes/IMU2FL.STL" />
      </geometry>
    </collision>
  </link>
  <joint
    name="IMU2FL_ShFL"
    type="fixed">
    <origin
      xyz="0.16803 0.013888 0.024775"
      rpy="0 0 -2.3788" />
    <parent
      link="ShFL" />
    <child
      link="IMU2FL" />
    <axis
      xyz="0 0 0" />
  </joint>
  <link
    name="SeBL">
    <inertial>
      <origin
        xyz="-0.00039965 0.00024478 0.025144"
        rpy="0 0 0" />
      <mass
        value="0.037021" />
      <inertia
        ixx="5.4169E-06"
        ixy="-9.1221E-09"
        ixz="2.0494E-08"
        iyy="5.0821E-06"
        iyz="-1.3847E-08"
        izz="3.2296E-06" />
    </inertial>
    <visual>
      <origin
        xyz="0 0 0"
        rpy="0 0 0" />
      <geometry>
        <mesh
          filename="package://CERBERUS_V1/meshes/SeBL.STL" />
      </geometry>
      <material
        name="">
        <color
          rgba="0.89804 0.91765 0.92941 1" />
      </material>
    </visual>
    <collision>
      <origin
        xyz="0 0 0"
        rpy="0 0 0" />
      <geometry>
        <mesh
          filename="package://CERBERUS_V1/meshes/SeBL.STL" />
      </geometry>
    </collision>
  </link>
  <joint
    name="SeBL_M"
    type="revolute">
    <origin
      xyz="-0.1154 0.095 0.044"
      rpy="1.5708 0 1.5708" />
    <parent
      link="M" />
    <child
      link="SeBL" />
    <axis
      xyz="0 0 -1" />
    <limit
      lower="-0.7854"
      upper="0.7854"
      effort="1.7"
      velocity="6.545" />
    <dynamics
      damping="0.025"
      friction="0.12" />
    <safety_controller
      soft_upper_limit="0.7"
      soft_lower_limit="-0.7"
      k_velocity="0" />
  </joint>
  <link
    name="ThBL">
    <inertial>
      <origin
        xyz="-0.065249 -0.0067576 0.024344"
        rpy="0 0 0" />
      <mass
        value="0.2297" />
      <inertia
        ixx="4.5425E-05"
        ixy="-2.0512E-05"
        ixz="4.5799E-06"
        iyy="0.00063156"
        iyz="-6.9302E-07"
        izz="0.00064269" />
    </inertial>
    <visual>
      <origin
        xyz="0 0 0"
        rpy="0 0 0" />
      <geometry>
        <mesh
          filename="package://CERBERUS_V1/meshes/ThBL.STL" />
      </geometry>
      <material
        name="">
        <color
          rgba="0.89804 0.91765 0.92941 1" />
      </material>
    </visual>
    <collision>
      <origin
        xyz="0 0 0"
        rpy="0 0 0" />
      <geometry>
        <mesh
          filename="package://CERBERUS_V1/meshes/ThBL.STL" />
      </geometry>
    </collision>
  </link>
  <joint
    name="ThBL_SeBL"
    type="revolute">
    <origin
      xyz="0.0144 2.8116E-05 0.045901"
      rpy="1.5708 -0.70732 1.5708" />
    <parent
      link="SeBL" />
    <child
      link="ThBL" />
    <axis
      xyz="0 0 -1" />
    <limit
      lower="-0.7854"
      upper="0.7854"
      effort="1.7"
      velocity="6.545" />
    <dynamics
      damping="0.025"
      friction="0.12" />
    <safety_controller
      soft_upper_limit="0.7"
      soft_lower_limit="-0.7"
      k_velocity="0" />
  </joint>
  <link
    name="ArBL">
    <inertial>
      <origin
        xyz="-2.7735E-05 0.007627 0.0033028"
        rpy="0 0 0" />
      <mass
        value="0.0030347" />
      <inertia
        ixx="2.989E-07"
        ixy="4.865E-09"
        ixz="2.5487E-11"
        iyy="4.3267E-08"
        iyz="-5.0977E-09"
        izz="3.2577E-07" />
    </inertial>
    <visual>
      <origin
        xyz="0 0 0"
        rpy="0 0 0" />
      <geometry>
        <mesh
          filename="package://CERBERUS_V1/meshes/ArBL.STL" />
      </geometry>
      <material
        name="">
        <color
          rgba="0.89804 0.91765 0.92941 1" />
      </material>
    </visual>
    <collision>
      <origin
        xyz="0 0 0"
        rpy="0 0 0" />
      <geometry>
        <mesh
          filename="package://CERBERUS_V1/meshes/ArBL.STL" />
      </geometry>
    </collision>
  </link>
  <joint
    name="ArBL_ThBL"
    type="revolute">
    <origin
      xyz="-0.050268 -0.027324 0.025077"
      rpy="1.5708 0 0" />
    <parent
      link="ThBL" />
    <child
      link="ArBL" />
    <axis
      xyz="0 0 -1" />
    <limit
      lower="-0.7854"
      upper="0.7854"
      effort="1.7"
      velocity="6.545" />
    <dynamics
      damping="0.025"
      friction="0.12" />
    <safety_controller
      soft_upper_limit="0.7"
      soft_lower_limit="-0.7"
      k_velocity="0" />
  </joint>
  <link
    name="IMU1BL">
    <inertial>
      <origin
        xyz="0 0 0.0015"
        rpy="0 0 0" />
      <mass
        value="0.0009" />
      <inertia
        ixx="1.755E-08"
        ixy="0"
        ixz="1.2677E-23"
        iyy="3.0675E-08"
        iyz="7.1312E-24"
        izz="4.6875E-08" />
    </inertial>
    <visual>
      <origin
        xyz="0 0 0"
        rpy="0 0 0" />
      <geometry>
        <mesh
          filename="package://CERBERUS_V1/meshes/IMU1BL.STL" />
      </geometry>
      <material
        name="">
        <color
          rgba="0 1 0 1" />
      </material>
    </visual>
    <collision>
      <origin
        xyz="0 0 0"
        rpy="0 0 0" />
      <geometry>
        <mesh
          filename="package://CERBERUS_V1/meshes/IMU1BL.STL" />
      </geometry>
    </collision>
  </link>
  <joint
    name="IMU1BL_ThBL"
    type="fixed">
    <origin
      xyz="-0.079757 -0.006231 0.04015"
      rpy="0 0 0.077967" />
    <parent
      link="ThBL" />
    <child
      link="IMU1BL" />
    <axis
      xyz="0 0 0" />
  </joint>
  <link
    name="ShBL">
    <inertial>
      <origin
        xyz="0.067367 -0.0073554 0.01484"
        rpy="0 0 0" />
      <mass
        value="0.088995" />
      <inertia
        ixx="1.0044E-05"
        ixy="1.8089E-05"
        ixz="3.9307E-09"
        iyy="0.00024333"
        iyz="-1.2557E-10"
        izz="0.00024934" />
    </inertial>
    <visual>
      <origin
        xyz="0 0 0"
        rpy="0 0 0" />
      <geometry>
        <mesh
          filename="package://CERBERUS_V1/meshes/ShBL.STL" />
      </geometry>
      <material
        name="">
        <color
          rgba="0.5451 0.61569 0.85882 1" />
      </material>
    </visual>
    <collision>
      <origin
        xyz="0 0 0"
        rpy="0 0 0" />
      <geometry>
        <mesh
          filename="package://CERBERUS_V1/meshes/ShBL.STL" />
      </geometry>
    </collision>
  </link>
  <joint
    name="ShBL_ThBL"
    type="revolute">
    <origin
      xyz="-0.18101 0.0059195 0.01015"
      rpy="0 0 1.6483" />
    <parent
      link="ThBL" />
    <child
      link="ShBL" />
    <axis
      xyz="0 0 -1" />
    <limit
      lower="-0.7854"
      upper="0.7854"
      effort="1.7"
      velocity="6.545" />
    <dynamics
      damping="0.025"
      friction="0.12" />
    <safety_controller
      soft_upper_limit="0.7"
      soft_lower_limit="-0.7"
      k_velocity="0" />
    <mimic
      joint="ArBL_ThBL"
      multiplier="-0.2824"
      offset="0" />
  </joint>
  <link
    name="IMU2BL">
    <inertial>
      <origin
        xyz="3.6082E-16 -2.6368E-16 0.0015"
        rpy="0 0 0" />
      <mass
        value="0.0009" />
      <inertia
        ixx="1.755E-08"
        ixy="-3.4638E-24"
        ixz="9.656E-24"
        iyy="3.0675E-08"
        iyz="1.5003E-24"
        izz="4.6875E-08" />
    </inertial>
    <visual>
      <origin
        xyz="0 0 0"
        rpy="0 0 0" />
      <geometry>
        <mesh
          filename="package://CERBERUS_V1/meshes/IMU2BL.STL" />
      </geometry>
      <material
        name="">
        <color
          rgba="0 1 0 1" />
      </material>
    </visual>
    <collision>
      <origin
        xyz="0 0 0"
        rpy="0 0 0" />
      <geometry>
        <mesh
          filename="package://CERBERUS_V1/meshes/IMU2BL.STL" />
      </geometry>
    </collision>
  </link>
  <joint
    name="IMU2BL_ShBL"
    type="fixed">
    <origin
      xyz="0.16803 0.013888 0.024775"
      rpy="0 0 -2.3788" />
    <parent
      link="ShBL" />
    <child
      link="IMU2BL" />
    <axis
      xyz="0 0 0" />
  </joint>
</robot>